# 错误处理

### 内部try...catch

函数内部用到了`try...catch`则让其在`catch`时返回一个包含错误信息的返回值，在调用的时候，只需要检查返回值中有没有错误就可以了



### 调用try...catch

函数内没有写`try...catch`，只针对特定的情况`throw new Error`，调用的时候需要`try...catch`